Q1

空的exception被rethrow，直接結束程式


Q2

會，有被catch，所以會繼續往下執行


Q3

result:
Exception: std::bad_alloc
